Workbook

Sheet 00.읽기전에
A1: 스탠다드 소싱계산기 템플릿
A3: 이 파일은 <오픈마켓 베스트셀러 카피 전략> 스탠다드 전자책과 함께 쓰는 실전 워크시트입니다.
A5: 사용 순서:
A6: 1) 02.마진계산기 — 상품명·원가·마진율·카테고리만 입력하면 플랫폼별 판매가/실정산가가 자동 계산됩니다.
A7: 2) 03.수수료 — 카테고리별 실제 플랫폼 수수료 참고표입니다. 02번 시트가 이 표를 자동으로 참조합니다.
A8: 3) 05.구매시트 — 실제 주문이 들어와서 소싱채널에서 발주할 때 기록하는 시트입니다. 마진/수익률이 자동 계산됩니다.
A9: 4) 06.취소교환반품 — 반품/교환 건을 기록하고 손실 금액을 관리합니다.
A10: 5) 소싱금지브랜드 — 등록 전 꼭 확인하세요. 시간이 지나면 바뀌는 목록이니 주기적으로 직접 재확인이 필요합니다.
A11: 6) CS응대스크립트 — 자주 오는 문의 7가지에 대한 답변 템플릿입니다.
A13: 입력 규칙:
A14: - 파란 글자 = 직접 입력하는 칸
A15: - 검은 글자 = 자동 계산되는 수식 (건드리지 마세요)
... A19: 실제 판매가를 확정하기 전 각 플랫폼 판매자센터 공지에서 최신 수수료를 반드시 재확인하세요.

Sheet 03.수수료
A1: 카테고리 | B1: 네이버_총수수료 | C1: 카카오_총수수료 | D1: 쿠팡_총수수료 | E1: 오픈마켓_총수수료 | F1: 셀러허브_총수수료 | G1: 토스쇼핑_총수수료
A2: 참고: 오픈마켓(지마켓/옥션/11번가/롯데온 등) 쿠폰 비용은 플랫폼이 85%, 판매자가 15%만 부담하는 구조가 일반적입니다. 아래 총수수료는 이 쿠폰 부담분까지 반영한 값입니다. (기준 시점 참고값 — 실제 적용 전 각 플랫폼 공지 재확인 필수)
A3: 물티슈 | B3: 0.04 | C3: 0.055 | D3: 0.0858 | E3: 0.1359 | F3: 0.15 | G3: 0.108
A4: 식품/건강 | B4: 0.04 | C4: 0.055 | D4: 0.1199 | E4: 0.1865 | F4: 0.15 | G4: 0.108
A5: 펫/반려 | B5: 0.04 | C5: 0.055 | D5: 0.1188 | E5: 0.1865 | F5: 0.15 | G5: 0.108
A6: 욕실/세탁세제 | B6: 0.04 | C6: 0.055 | D6: 0.0858 | E6: 0.1612 | F6: 0.15 | G6: 0.108
A7: 샴푸/바디워시 등 | B7: 0.04 | C7: 0.055 | D7: 0.1056 | E7: 0.1612 | F7: 0.15 | G7: 0.108
A8: 출산/유아동 | B8: 0.04 | C8: 0.055 | D8: 0.0858 | E8: 0.1359 | F8: 0.15 | G8: 0.108
A9: 건강식품/다이어트 | B9: 0.04 | C9: 0.055 | D9: 0.1166 | E9: 0.1865 | F9: 0.15 | G9: 0.108
A10: 뷰티/퍼스널케어 | B10: 0.04 | C10: 0.055 | D10: 0.1056 | E10: 0.1865 | F10: 0.15 | G10: 0.108
A11: 가전/디지털 | B11: 0.04 | C11: 0.055 | D11: 0.0858 | E11: 0.1359 | F11: 0.15 | G11: 0.108
A12: 자동차/레저 | B12: 0.04 | C12: 0.055 | D12: 0.1188 | E12: 0.1865 | F12: 0.15 | G12: 0.108
A13: 노트북/PC | B13: 0.04 | C13: 0.055 | D13: 0.0704 | E13: 0.1106 | F13: 0.15 | G13: 0.108
A14: 홈/리빙 | B14: 0.04 | C14: 0.055 | D14: 0.1188 | E14: 0.1865 | F14: 0.15 | G14: 0.108
A15: 제지류/화장지 | B15: 0.04 | C15: 0.055 | D15: 0.0858 | E15: 0.1359 | F15: 0.15 | G15: 0.108

Sheet 02.마진계산기
A1: 구분 | B1: 상품명 | C1: 글자수(60자이내) | D1: 링크 | E1: 원가 | F1: 마진율 | G1: 정산가(목표 실수령액) | H1: 카테고리 | I1: 네이버_판매가 | J1: 네이버_실정산가 | K1: 카카오_판매가 | L1: 카카오_실정산가 | M1: 쿠팡_판매가 | N1: 쿠팡_실정산가 | O1: 오픈마켓_판매가 | P1: 오픈마켓_실정산가 | Q1: 셀러허브_판매가 | R1: 셀러허브_실정산가 | S1: 토스쇼핑_판매가 | T1: 토스쇼핑_실정산가 | U1: 비고
A2: 예시 | B2: OO브랜드 비타민C 60정 | C2: =IFERROR(LEN(B2),"") | D2: https://item.gmarket.co.kr/Item?... | E2: 12000 | F2: 0.15 | G2: =IFERROR(E2*(1+F2),"") | H2: 건강식품/다이어트 | I2: =IFERROR($G2/(1-IFERROR(INDEX('03.수수료'!$B:$B,MATCH($H2,'03.수수료'!$A:$A,0)),"")),"") | J2: =IFERROR(I2*(1-IFERROR(INDEX('03.수수료'!$B:$B,MATCH($H2,'03.수수료'!$A:$A,0)),"")),"") | K2: =IFERROR($G2/(1-IFERROR(INDEX('03.수수료'!$C:$C,MATCH($H2,'03.수수료'!$A:$A,0)),"")),"") | L2: =IFERROR(K2*(1-IFERROR(INDEX('03.수수료'!$C:$C,MATCH($H2,'03.수수료'!$A:$A,0)),"")),"") | M2: =IFERROR($G2/(1-IFERROR(INDEX('03.수수료'!$D:$D,MATCH($H2,'03.수수료'!$A:$A,0)),"")),"") | N2: =IFERROR(M2*(1-IFERROR(INDEX('03.수수료'!$D:$D,MATCH($H2,'03.수수료'!$A:$A,0)),"")),"") | O2: =IFERROR($G2/(1-IFERROR(INDEX('03.수수료'!$E:$E,MATCH($H2,'03.수수료'!$A:$A,0)),"")),"") | P2: =IFERROR(O2*(1-IFERROR(INDEX('03.수수료'!$E:$E,MATCH($H2,'03.수수료'!$A:$A,0)),"")),"") | Q2: =IFERROR($G2/(1-IFERROR(INDEX('03.수수료'!$F:$F,MATCH($H2,'03.수수료'!$A:$A,0)),"")),"") | R2: =IFERROR(Q2*(1-IFERROR(INDEX('03.수수료'!$F:$F,MATCH($H2,'03.수수료'!$A:$A,0)),"")),"") | S2: =IFERROR($G2/(1-IFERROR(INDEX('03.수수료'!$G:$G,MATCH($H2,'03.수수료'!$A:$A,0)),"")),"") | T2: =IFERROR(S2*(1-IFERROR(INDEX('03.수수료'!$G:$G,MATCH($H2,'03.수수료'!$A:$A,0)),"")),"")
C3: =IFERROR(LEN(B3),"") | G3: =IFERROR(E3*(1+F3),"") | I3: =IFERROR($G3/(1-IFERROR(INDEX('03.수수료'!$B:$B,MATCH($H3,'03.수수료'!$A:$A,0)),"")),"") | J3: =IFERROR(I3*(1-IFERROR(INDEX('03.수수료'!$B:$B,MATCH($H3,'03.수수료'!$A:$A,0)),"")),"") | K3: =IFERROR($G3/(1-IFERROR(INDEX('03.수수료'!$C:$C,MATCH($H3,'03.수수료'!$A:$A,0)),"")),"") | L3: =IFERROR(K3*(1-IFERROR(INDEX('03.수수료'!$C:$C,MATCH($H3,'03.수수료'!$A:$A,0)),"")),"") | M3: =IFERROR($G3/(1-IFERROR(INDEX('03.수수료'!$D:$D,MATCH($H3,'03.수수료'!$A:$A,0)),"")),"") | N3: =IFERROR(M3*(1-IFERROR(INDEX('03.수수료'!$D:$D,MATCH($H3,'03.수수료'!$A:$A,0)),"")),"") | O3: =IFERROR($G3/(1-IFERROR(INDEX('03.수수료'!$E:$E,MATCH($H3,'03.수수료'!$A:$A,0)),"")),"") | P3: =IFERROR(O3*(1-IFERROR(INDEX('03.수수료'!$E:$E,MATCH($H3,'03.수수료'!$A:$A,0)),"")),"") | Q3: =IFERROR($G3/(1-IFERROR(INDEX('03.수수료'!$F:$F,MATCH($H3,'03.수수료'!$A:$A,0)),"")),"") | R3: =IFERROR(Q3*(1-IFERROR(INDEX('03.수수료'!$F:$F,MATCH($H3,'03.수수료'!$A:$A,0)),"")),"") | S3: =IFERROR($G3/(1-IFERROR(INDEX('03.수수료'!$G:$G,MATCH($H3,'03.수수료'!$A:$A,0)),"")),"") | T3: =IFERROR(S3*(1-IFERROR(INDEX('03.수수료'!$G:$G,MATCH($H3,'03.수수료'!$A:$A,0)),"")),"")
C4: =IFERROR(LEN(B4),"") | G4: =IFERROR(E4*(1+F4),"") | I4: =IFERROR($G4/(1-IFERROR(INDEX('03.수수료'!$B:$B,MATCH($H4,'03.수수료'!$A:$A,0)),"")),"") | J4: =IFERROR(I4*(1-IFERROR(INDEX('03.수수료'!$B:$B,MATCH($H4,'03.수수료'!$A:$A,0)),"")),"") | K4: =IFERROR($G4/(1-IFERROR(INDEX('03.수수료'!$C:$C,MATCH($H4,'03.수수료'!$A:$A,0)),"")),"") | L4: =IFERROR(K4*(1-IFERROR(INDEX('03.수수료'!$C:$C,MATCH($H4,'03.수수료'!$A:$A,0)),"")),"") | M4: =IFERROR($G4/(1-IFERROR(INDEX('03.수수료'!$D:$D,MATCH($H4,'03.수수료'!$A:$A,0)),"")),"") | N4: =IFERROR(M4*(1-IFERROR(INDEX('03.수수료'!$D:$D,MATCH($H4,'03.수수료'!$A:$A,0)),"")),"") | O4: =IFERROR($G4/(1-IFERROR(INDEX('03.수수료'!$E:$E,MATCH($H4,'03.수수료'!$A:$A,0)),"")),"") | P4: =IFERROR(O4*(1-IFERROR(INDEX('03.수수료'!$E:$E,MATCH($H4,'03.수수료'!$A:$A,0)),"")),"") | Q4: =IFERROR($G4/(1-IFERROR(INDEX('03.수수료'!$F:$F,MATCH($H4,'03.수수료'!$A:$A,0)),"")),"") | R4: =IFERROR(Q4*(1-IFERROR(INDEX('03.수수료'!$F:$F,MATCH($H4,'03.수수료'!$A:$A,0)),"")),"") | S4: =IFERROR($G4/(1-IFERROR(INDEX('03.수수료'!$G:$G,MATCH($H4,'03.수수료'!$A:$A,0)),"")),"") | T4: =IFERROR(S4*(1-IFERROR(INDEX('03.수수료'!$G:$G,MATCH($H4,'03.수수료'!$A:$A,0)),"")),"")
C5: =IFERROR(LEN(B5),"") | G5: =IFERROR(E5*(1+F5),"") | I5: =IFERROR($G5/(1-IFERROR(INDEX('03.수수료'!$B:$B,MATCH($H5,'03.수수료'!$A:$A,0)),"")),"") | J5: =IFERROR(I5*(1-IFERROR(INDEX('03.수수료'!$B:$B,MATCH($H5,'03.수수료'!$A:$A,0)),"")),"") | K5: =IFERROR($G5/(1-IFERROR(INDEX('03.수수료'!$C:$C,MATCH($H5,'03.수수료'!$A:$A,0)),"")),"") | L5: =IFERROR(K5*(1-IFERROR(INDEX('03.수수료'!$C:$C,MATCH($H5,'03.수수료'!$A:$A,0)),"")),"") | M5: =IFERROR($G5/(1-IFERROR(INDEX('03.수수료'!$D:$D,MATCH($H5,'03.수수료'!$A:$A,0)),"")),"") | N5: =IFERROR(M5*(1-IFERROR(INDEX('03.수수료'!$D:$D,MATCH($H5,'03.수수료'!$A:$A,0)),"")),"") | O5: =IFERROR($G5/(1-IFERROR(INDEX('03.수수료'!$E:$E,MATCH($H5,'03.수수료'!$A:$A,0)),"")),"") | P5: =IFERROR(O5*(1-IFERROR(INDEX('03.수수료'!$E:$E,MATCH($H5,'03.수수료'!$A:$A,0)),"")),"") | Q5: =IFERROR($G5/(1-IFERROR(INDEX('03.수수료'!$F:$F,MATCH($H5,'03.수수료'!$A:$A,0)),"")),"") | R5: =IFERROR(Q5*(1-IFERROR(INDEX('03.수수료'!$F:$F,MATCH($H5,'03.수수료'!$A:$A,0)),"")),"") | S5: =IFERROR($G5/(1-IFERROR(INDEX('03.수수료'!$G:$G,MATCH($H5,'03.수수료'!$A:$A,0)),"")),"") | T5: =IFERROR(S5*(1-IFERROR(INDEX('03.수수료'!$G:$G,MATCH($H5,'03.수수료'!$A:$A,0)),"")),"")
C6: =IFERROR(LEN(B6),"") | G6: =IFERROR(E6*(1+F6),"") | I6: =IFERROR($G6/(1-IFERROR(INDEX('03.수수료'!$B:$B,MATCH($H6,'03.수수료'!$A:$A,0)),"")),"") | J6: =IFERROR(I6*(1-IFERROR(INDEX('03.수수료'!$B:$B,MATCH($H6,'03.수수료'!$A:$A,0)),"")),"") | K6: =IFERROR($G6/(1-IFERROR(INDEX('03.수수료'!$C:$C,MATCH($H6,'03.수수료'!$A:$A,0)),"")),"") | L6: =IFERROR(K6*(1-IFERROR(INDEX('03.수수료'!$C:$C,MATCH($H6,'03.수수료'!$A:$A,0)),"")),"") | M6: =IFERROR($G6/(1-IFERROR(INDEX('03.수수료'!$D:$D,MATCH($H6,'03.수수료'!$A:$A,0)),"")),"") | N6: =IFERROR(M6*(1-IFERROR(INDEX('03.수수료'!$D:$D,MATCH($H6,'03.수수료'!$A:$A,0)),"")),"") | O6: =IFERROR($G6/(1-IFERROR(INDEX('03.수수료'!$E:$E,MATCH($H6,'03.수수료'!$A:$A,0)),"")),"") | P6: =IFERROR(O6*(1-IFERROR(INDEX('03.수수료'!$E:$E,MATCH($H6,'03.수수료'!$A:$A,0)),"")),"") | Q6: =IFERROR($G6/(1-IFERROR(INDEX('03.수수료'!$F:$F,MATCH($H6,'03.수수료'!$A:$A,0)),"")),"") | R6: =IFERROR(Q6*(1-IFERROR(INDEX('03.수수료'!$F:$F,MATCH($H6,'03.수수료'!$A:$A,0)),"")),"") | S6: =IFERROR($G6/(1-IFERROR(INDEX('03.수수료'!$G:$G,MATCH($H6,'03.수수료'!$A:$A,0)),"")),"") | T6: =IFERROR(S6*(1-IFERROR(INDEX('03.수수료'!$G:$G,MATCH($H6,'03.수수료'!$A:$A,0)),"")),"")
C7: =IFERROR(LEN(B7),"") | G7: =IFERROR(E7*(1+F7),"") | I7: =IFERROR($G7/(1-IFERROR(INDEX('03.수수료'!$B:$B,MATCH($H7,'03.수수료'!$A:$A,0)),"")),"") | J7: =IFERROR(I7*(1-IFERROR(INDEX('03.수수료'!$B:$B,MATCH($H7,'03.수수료'!$A:$A,0)),"")),"") | K7: =IFERROR($G7/(1-IFERROR(INDEX('03.수수료'!$C:$C,MATCH($H7,'03.수수료'!$A:$A,0)),"")),"") | L7: =IFERROR(K7*(1-IFERROR(INDEX('03.수수료'!$C:$C,MATCH($H7,'03.수수료'!$A:$A,0)),"")),"") | M7: =IFERROR($G7/(1-IFERROR(INDEX('03.수수료'!$D:$D,MATCH($H7,'03.수수료'!$A:$A,0)),"")),"") | N7: =IFERROR(M7*(1-IFERROR(INDEX('03.수수료'!$D:$D,MATCH($H7,'03.수수료'!$A:$A,0)),"")),"") | O7: =IFERROR($G7/(1-IFERROR(INDEX('03.수수료'!$E:$E,MATCH($H7,'03.수수료'!$A:$A,0)),"")),"") | P7: =IFERROR(O7*(1-IFERROR(INDEX('03.수수료'!$E:$E,MATCH($H7,'03.수수료'!$A:$A,0)),"")),"") | Q7: =IFERROR($G7/(1-IFERROR(INDEX('03.수수료'!$F:$F,MATCH($H7,'03.수수료'!$A:$A,0)),"")),"") | R7: =IFERROR(Q7*(1-IFERROR(INDEX('03.수수료'!$F:$F,MATCH($H7,'03.수수료'!$A:$A,0)),"")),"") | S7: =IFERROR($G7/(1-IFERROR(INDEX('03.수수료'!$G:$G,MATCH($H7,'03.수수료'!$A:$A,0)),"")),"") | T7: =IFERROR(S7*(1-IFERROR(INDEX('03.수수료'!$G:$G,MATCH($H7,'03.수수료'!$A:$A,0)),"")),"")
C8: =IFERROR(LEN(B8),"") | G8: =IFERROR(E8*(1+F8),"") | I8: =IFERROR($G8/(1-IFERROR(INDEX('03.수수료'!$B:$B,MATCH($H8,'03.수수료'!$A:$A,0)),"")),"") | J8: =IFERROR(I8*(1-IFERROR(INDEX('03.수수료'!$B:$B,MATCH($H8,'03.수수료'!$A:$A,0)),"")),"") | K8: =IFERROR($G8/(1-IFERROR(INDEX('03.수수료'!$C:$C,MATCH($H8,'03.수수료'!$A:$A,0)),"")),"") | L8: =IFERROR(K8*(1-IFERROR(INDEX('03.수수료'!$C:$C,MATCH($H8,'03.수수료'!$A:$A,0)),"")),"") | M8: =IFERROR($G8/(1-IFERROR(INDEX('03.수수료'!$D:$D,MATCH($H8,'03.수수료'!$A:$A,0)),"")),"") | N8: =IFERROR(M8*(1-IFERROR(INDEX('03.수수료'!$D:$D,MATCH($H8,'03.수수료'!$A:$A,0)),"")),"") | O8: =IFERROR($G8/(1-IFERROR(INDEX('03.수수료'!$E:$E,MATCH($H8,'03.수수료'!$A:$A,0)),"")),"") | P8: =IFERROR(O8*(1-IFERROR(INDEX('03.수수료'!$E:$E,MATCH($H8,'03.수수료'!$A:$A,0)),"")),"") | Q8: =IFERROR($G8/(1-IFERROR(INDEX('03.수수료'!$F:$F,MATCH($H8,'03.수수료'!$A:$A,0)),"")),"") | R8: =IFERROR(Q8*(1-IFERROR(INDEX('03.수수료'!$F:$F,MATCH($H8,'03.수수료'!$A:$A,0)),"")),"") | S8: =IFERROR($G8/(1-IFERROR(INDEX('03.수수료'!$G:$G,MATCH($H8,'03.수수료'!$A:$A,0)),"")),"") | T8: =IFERROR(S8*(1-IFERROR(INDEX('03.수수료'!$G:$G,MATCH($H8,'03.수수료'!$A:$A,0)),"")),"")
C9: =IFERROR(LEN(B9),"") | G9: =IFERROR(E9*(1+F9),"") | I9: =IFERROR($G9/(1-IFERROR(INDEX('03.수수료'!$B:$B,MATCH($H9,'03.수수료'!$A:$A,0)),"")),"") | J9: =IFERROR(I9*(1-IFERROR(INDEX('03.수수료'!$B:$B,MATCH($H9,'03.수수료'!$A:$A,0)),"")),"") | K9: =IFERROR($G9/(1-IFERROR(INDEX('03.수수료'!$C:$C,MATCH($H9,'03.수수료'!$A:$A,0)),"")),"") | L9: =IFERROR(K9*(1-IFERROR(INDEX('03.수수료'!$C:$C,MATCH($H9,'03.수수료'!$A:$A,0)),"")),"") | M9: =IFERROR($G9/(1-IFERROR(INDEX('03.수수료'!$D:$D,MATCH($H9,'03.수수료'!$A:$A,0)),"")),"") | N9: =IFERROR(M9*(1-IFERROR(INDEX('03.수수료'!$D:$D,MATCH($H9,'03.수수료'!$A:$A,0)),"")),"") | O9: =IFERROR($G9/(1-IFERROR(INDEX('03.수수료'!$E:$E,MATCH($H9,'03.수수료'!$A:$A,0)),"")),"") | P9: =IFERROR(O9*(1-IFERROR(INDEX('03.수수료'!$E:$E,MATCH($H9,'03.수수료'!$A:$A,0)),"")),"") | Q9: =IFERROR($G9/(1-IFERROR(INDEX('03.수수료'!$F:$F,MATCH($H9,'03.수수료'!$A:$A,0)),"")),"") | R9: =IFERROR(Q9*(1-IFERROR(INDEX('03.수수료'!$F:$F,MATCH($H9,'03.수수료'!$A:$A,0)),"")),"") | S9: =IFERROR($G9/(1-IFERROR(INDEX('03.수수료'!$G:$G,MATCH($H9,'03.수수료'!$A:$A,0)),"")),"") | T9: =IFERROR(S9*(1-IFERROR(INDEX('03.수수료'!$G:$G,MATCH($H9,'03.수수료'!$A:$A,0)),"")),"")
C10: =IFERROR(LEN(B10),"") | G10: =IFERROR(E10*(1+F10),"") | I10: =IFERROR($G10/(1-IFERROR(INDEX('03.수수료'!$B:$B,MATCH($H10,'03.수수료'!$A:$A,0)),"")),"") | J10: =IFERROR(I10*(1-IFERROR(INDEX('03.수수료'!$B:$B,MATCH($H10,'03.수수료'!$A:$A,0)),"")),"") | K10: =IFERROR($G10/(1-IFERROR(INDEX('03.수수료'!$C:$C,MATCH($H10,'03.수수료'!$A:$A,0)),"")),"") | L10: =IFERROR(K10*(1-IFERROR(INDEX('03.수수료'!$C:$C,MATCH($H10,'03.수수료'!$A:$A,0)),"")),"") | M10: =IFERROR($G10/(1-IFERROR(INDEX('03.수수료'!$D:$D,MATCH($H10,'03.수수료'!$A:$A,0)),"")),"") | N10: =IFERROR(M10*(1-IFERROR(INDEX('03.수수료'!$D:$D,MATCH($H10,'03.수수료'!$A:$A,0)),"")),"") | O10: =IFERROR($G10/(1-IFERROR(INDEX('03.수수료'!$E:$E,MATCH($H10,'03.수수료'!$A:$A,0)),"")),"") | P10: =IFERROR(O10*(1-IFERROR(INDEX('03.수수료'!$E:$E,MATCH($H10,'03.수수료'!$A:$A,0)),"")),"") | Q10: =IFERROR($G10/(1-IFERROR(INDEX('03.수수료'!$F:$F,MATCH($H10,'03.수수료'!$A:$A,0)),"")),"") | R10: =IFERROR(Q10*(1-IFERROR(INDEX('03.수수료'!$F:$F,MATCH($H10,'03.수수료'!$A:$A,0)),"")),"") | S10: =IFERROR($G10/(1-IFERROR(INDEX('03.수수료'!$G:$G,MATCH($H10,'03.수수료'!$A:$A,0)),"")),"") | T10: =IFERROR(S10*(1-IFERROR(INDEX('03.수수료'!$G:$G,MATCH($H10,'03.수수료'!$A:$A,0)),"")),"")
C11: =IFERROR(LEN(B11),"") | G11: =IFERROR(E11*(1+F11),"") | I11: =IFERROR($G11/(1-IFERROR(INDEX('03.수수료'!$B:$B,MATCH($H11,'03.수수료'!$A:$A,0)),"")),"") | J11: =IFERROR(I11*(1-IFERROR(INDEX('03.수수료'!$B:$B,MATCH($H11,'03.수수료'!$A:$A,0)),"")),"") | K11: =IFERROR($G11/(1-IFERROR(INDEX('03.수수료'!$C:$C,MATCH($H11,'03.수수료'!$A:$A,0)),"")),"") | L11: =IFERROR(K11*(1-IFERROR(INDEX('03.수수료'!$C:$C,MATCH($H11,'03.수수료'!$A:$A,0)),"")),"") | M11: =IFERROR($G11/(1-IFERROR(INDEX('03.수수료'!$D:$D,MATCH($H11,'03.수수료'!$A:$A,0)),"")),"") | N11: =IFERROR(M11*(1-IFERROR(INDEX('03.수수료'!$D:$D,MATCH($H11,'03.수수료'!$A:$A,0)),"")),"") | O11: =IFERROR($G11/(1-IFERROR(INDEX('03.수수료'!$E:$E,MATCH($H11,'03.수수료'!$A:$A,0)),"")),"") | P11: =IFERROR(O11*(1-IFERROR(INDEX('03.수수료'!$E:$E,MATCH($H11,'03.수수료'!$A:$A,0)),"")),"") | Q11: =IFERROR($G11/(1-IFERROR(INDEX('03.수수료'!$F:$F,MATCH($H11,'03.수수료'!$A:$A,0)),"")),"") | R11: =IFERROR(Q11*(1-IFERROR(INDEX('03.수수료'!$F:$F,MATCH($H11,'03.수수료'!$A:$A,0)),"")),"") | S11: =IFERROR($G11/(1-IFERROR(INDEX('03.수수료'!$G:$G,MATCH($H11,'03.수수료'!$A:$A,0)),"")),"") | T11: =IFERROR(S11*(1-IFERROR(INDEX('03.수수료'!$G:$G,MATCH($H11,'03.수수료'!$A:$A,0)),"")),"")
C12: =IFERROR(LEN(B12),"") | G12: =IFERROR(E12*(1+F12),"") | I12: =IFERROR($G12/(1-IFERROR(INDEX('03.수수료'!$B:$B,MATCH($H12,'03.수수료'!$A:$A,0)),"")),"") | J12: =IFERROR(I12*(1-IFERROR(INDEX('03.수수료'!$B:$B,MATCH($H12,'03.수수료'!$A:$A,0)),"")),"") | K12: =IFERROR($G12/(1-IFERROR(INDEX('03.수수료'!$C:$C,MATCH($H12,'03.수수료'!$A:$A,0)),"")),"") | L12: =IFERROR(K12*(1-IFERROR(INDEX('03.수수료'!$C:$C,MATCH($H12,'03.수수료'!$A:$A,0)),"")),"") | M12: =IFERROR($G12/(1-IFERROR(INDEX('03.수수료'!$D:$D,MATCH($H12,'03.수수료'!$A:$A,0)),"")),"") | N12: =IFERROR(M12*(1-IFERROR(INDEX('03.수수료'!$D:$D,MATCH($H12,'03.수수료'!$A:$A,0)),"")),"") | O12: =IFERROR($G12/(1-IFERROR(INDEX('03.수수료'!$E:$E,MATCH($H12,'03.수수료'!$A:$A,0)),"")),"") | P12: =IFERROR(O12*(1-IFERROR(INDEX('03.수수료'!$E:$E,MATCH($H12,'03.수수료'!$A:$A,0)),"")),"") | Q12: =IFERROR($G12/(1-IFERROR(INDEX('03.수수료'!$F:$F,MATCH($H12,'03.수수료'!$A:$A,0)),"")),"") | R12: =IFERROR(Q12*(1-IFERROR(INDEX('03.수수료'!$F:$F,MATCH($H12,'03.수수료'!$A:$A,0)),"")),"") | S12: =IFERROR($G12/(1-IFERROR(INDEX('03.수수료'!$G:$G,MATCH($H12,'03.수수료'!$A:$A,0)),"")),"") | T12: =IFERROR(S12*(1-IFERROR(INDEX('03.수수료'!$G:$G,MATCH($H12,'03.수수료'!$A:$A,0)),"")),"")
C13: =IFERROR(LEN(B13),"") | G13: =IFERROR(E13*(1+F13),"") | I13: =IFERROR($G13/(1-IFERROR(INDEX('03.수수료'!$B:$B,MATCH($H13,'03.수수료'!$A:$A,0)),"")),"") | J13: =IFERROR(I13*(1-IFERROR(INDEX('03.수수료'!$B:$B,MATCH($H13,'03.수수료'!$A:$A,0)),"")),"") | K13: =IFERROR($G13/(1-IFERROR(INDEX('03.수수료'!$C:$C,MATCH($H13,'03.수수료'!$A:$A,0)),"")),"") | L13: =IFERROR(K13*(1-IFERROR(INDEX('03.수수료'!$C:$C,MATCH($H13,'03.수수료'!$A:$A,0)),"")),"") | M13: =IFERROR($G13/(1-IFERROR(INDEX('03.수수료'!$D:$D,MATCH($H13,'03.수수료'!$A:$A,0)),"")),"") | N13: =IFERROR(M13*(1-IFERROR(INDEX('03.수수료'!$D:$D,MATCH($H13,'03.수수료'!$A:$A,0)),"")),"") | O13: =IFERROR($G13/(1-IFERROR(INDEX('03.수수료'!$E:$E,MATCH($H13,'03.수수료'!$A:$A,0)),"")),"") | P13: =IFERROR(O13*(1-IFERROR(INDEX('03.수수료'!$E:$E,MATCH($H13,'03.수수료'!$A:$A,0)),"")),"") | Q13: =IFERROR($G13/(1-IFERROR(INDEX('03.수수료'!$F:$F,MATCH($H13,'03.수수료'!$A:$A,0)),"")),"") | R13: =IFERROR(Q13*(1-IFERROR(INDEX('03.수수료'!$F:$F,MATCH($H13,'03.수수료'!$A:$A,0)),"")),"") | S13: =IFERROR($G13/(1-IFERROR(INDEX('03.수수료'!$G:$G,MATCH($H13,'03.수수료'!$A:$A,0)),"")),"") | T13: =IFERROR(S13*(1-IFERROR(INDEX('03.수수료'!$G:$G,MATCH($H13,'03.수수료'!$A:$A,0)),"")),"")
C14: =IFERROR(LEN(B14),"") | G14: =IFERROR(E14*(1+F14),"") | I14: =IFERROR($G14/(1-IFERROR(INDEX('03.수수료'!$B:$B,MATCH($H14,'03.수수료'!$A:$A,0)),"")),"") | J14: =IFERROR(I14*(1-IFERROR(INDEX('03.수수료'!$B:$B,MATCH($H14,'03.수수료'!$A:$A,0)),"")),"") | K14: =IFERROR($G14/(1-IFERROR(INDEX('03.수수료'!$C:$C,MATCH($H14,'03.수수료'!$A:$A,0)),"")),"") | L14: =IFERROR(K14*(1-IFERROR(INDEX('03.수수료'!$C:$C,MATCH($H14,'03.수수료'!$A:$A,0)),"")),"") | M14: =IFERROR($G14/(1-IFERROR(INDEX('03.수수료'!$D:$D,MATCH($H14,'03.수수료'!$A:$A,0)),"")),"") | N14: =IFERROR(M14*(1-IFERROR(INDEX('03.수수료'!$D:$D,MATCH($H14,'03.수수료'!$A:$A,0)),"")),"") | O14: =IFERROR($G14/(1-IFERROR(INDEX('03.수수료'!$E:$E,MATCH($H14,'03.수수료'!$A:$A,0)),"")),"") | P14: =IFERROR(O14*(1-IFERROR(INDEX('03.수수료'!$E:$E,MATCH($H14,'03.수수료'!$A:$A,0)),"")),"") | Q14: =IFERROR($G14/(1-IFERROR(INDEX('03.수수료'!$F:$F,MATCH($H14,'03.수수료'!$A:$A,0)),"")),"") | R14: =IFERROR(Q14*(1-IFERROR(INDEX('03.수수료'!$F:$F,MATCH($H14,'03.수수료'!$A:$A,0)),"")),"") | S14: =IFERROR($G14/(1-IFERROR(INDEX('03.수수료'!$G:$G,MATCH($H14,'03.수수료'!$A:$A,0)),"")),"") | T14: =IFERROR(S14*(1-IFERROR(INDEX('03.수수료'!$G:$G,MATCH($H14,'03.수수료'!$A:$A,0)),"")),"")
... C30: =IFERROR(LEN(B30),"") | G30: =IFERROR(E30*(1+F30),"") | I30: =IFERROR($G30/(1-IFERROR(INDEX('03.수수료'!$B:$B,MATCH($H30,'03.수수료'!$A:$A,0)),"")),"") | J30: =IFERROR(I30*(1-IFERROR(INDEX('03.수수료'!$B:$B,MATCH($H30,'03.수수료'!$A:$A,0)),"")),"") | K30: =IFERROR($G30/(1-IFERROR(INDEX('03.수수료'!$C:$C,MATCH($H30,'03.수수료'!$A:$A,0)),"")),"") | L30: =IFERROR(K30*(1-IFERROR(INDEX('03.수수료'!$C:$C,MATCH($H30,'03.수수료'!$A:$A,0)),"")),"") | M30: =IFERROR($G30/(1-IFERROR(INDEX('03.수수료'!$D:$D,MATCH($H30,'03.수수료'!$A:$A,0)),"")),"") | N30: =IFERROR(M30*(1-IFERROR(INDEX('03.수수료'!$D:$D,MATCH($H30,'03.수수료'!$A:$A,0)),"")),"") | O30: =IFERROR($G30/(1-IFERROR(INDEX('03.수수료'!$E:$E,MATCH($H30,'03.수수료'!$A:$A,0)),"")),"") | P30: =IFERROR(O30*(1-IFERROR(INDEX('03.수수료'!$E:$E,MATCH($H30,'03.수수료'!$A:$A,0)),"")),"") | Q30: =IFERROR($G30/(1-IFERROR(INDEX('03.수수료'!$F:$F,MATCH($H30,'03.수수료'!$A:$A,0)),"")),"") | R30: =IFERROR(Q30*(1-IFERROR(INDEX('03.수수료'!$F:$F,MATCH($H30,'03.수수료'!$A:$A,0)),"")),"") | S30: =IFERROR($G30/(1-IFERROR(INDEX('03.수수료'!$G:$G,MATCH($H30,'03.수수료'!$A:$A,0)),"")),"") | T30: =IFERROR(S30*(1-IFERROR(INDEX('03.수수료'!$G:$G,MATCH($H30,'03.수수료'!$A:$A,0)),"")),"")
A32: 입력: 상품명(B) · 링크(D) · 원가(E) · 마진율(F) · 카테고리(G열의 03.수수료 시트와 동일한 이름으로 H에 입력) 만 채우면 나머지는 자동 계산됩니다.

Sheet 05.구매시트
A1: 날짜 | B1: 작업자 | C1: 쇼핑몰(판매채널) | D1: 수령자명 | E1: 휴대번호 | F1: 주소 | G1: 배송메세지 | H1: 상품명 | I1: 옵션 | J1: 수량 | K1: 플랫폼판매가격 | L1: 공급가(실구매가) | M1: 구매한곳(소싱채널) | N1: 구매계정 | O1: 구매가격 | P1: 결제카드 | Q1: 마진 | R1: 수익률 | S1: 마일리지 | T1: 비고
A2: 2026-09-01 | B2: 본인 | C2: 11번가 | D2: 홍길동 | E2: 010-0000-0000 | F2: 서울시 ... | G2: 부재시 문앞 | H2: OO브랜드 비타민C 60정 | I2: 단품 | J2: 1 | K2: 24000 | L2: =IFERROR(O2,"") | M2: 지마켓 | N2: 본계정 | O2: 19500 | P2: 현대스마일카드 | Q2: =IFERROR(K2-O2,"") | R2: =IFERROR(Q2/K2,"")
L3: =IFERROR(O3,"") | Q3: =IFERROR(K3-O3,"") | R3: =IFERROR(Q3/K3,"")
L4: =IFERROR(O4,"") | Q4: =IFERROR(K4-O4,"") | R4: =IFERROR(Q4/K4,"")
L5: =IFERROR(O5,"") | Q5: =IFERROR(K5-O5,"") | R5: =IFERROR(Q5/K5,"")
L6: =IFERROR(O6,"") | Q6: =IFERROR(K6-O6,"") | R6: =IFERROR(Q6/K6,"")
L7: =IFERROR(O7,"") | Q7: =IFERROR(K7-O7,"") | R7: =IFERROR(Q7/K7,"")
L8: =IFERROR(O8,"") | Q8: =IFERROR(K8-O8,"") | R8: =IFERROR(Q8/K8,"")
L9: =IFERROR(O9,"") | Q9: =IFERROR(K9-O9,"") | R9: =IFERROR(Q9/K9,"")
L10: =IFERROR(O10,"") | Q10: =IFERROR(K10-O10,"") | R10: =IFERROR(Q10/K10,"")
L11: =IFERROR(O11,"") | Q11: =IFERROR(K11-O11,"") | R11: =IFERROR(Q11/K11,"")
L12: =IFERROR(O12,"") | Q12: =IFERROR(K12-O12,"") | R12: =IFERROR(Q12/K12,"")
L13: =IFERROR(O13,"") | Q13: =IFERROR(K13-O13,"") | R13: =IFERROR(Q13/K13,"")
L14: =IFERROR(O14,"") | Q14: =IFERROR(K14-O14,"") | R14: =IFERROR(Q14/K14,"")
... L30: =IFERROR(O30,"") | Q30: =IFERROR(K30-O30,"") | R30: =IFERROR(Q30/K30,"")
A33: 월 요약
A34: 총 판매가 | B34: =SUM(K2:K31)
A35: 총 구매가 | B35: =SUM(O2:O31)
A36: 운영 이익 (판매가-구매가) | B36: =B34-B35
A37: 고정지출 합계 | B37: =SUM(E40:E46)
A38: 순이익(운영이익-고정지출) | B38: =B36-B37
D39: 고정지출 항목 (예시 — 본인 상황에 맞게 수정)
D40: 플레이오토 | E40: 150000
D41: 아이템스카우트 | E41: 12000
D42: 셀러허브 수수료 | E42: 60000
D43: 통신비(알뜰폰 등) | E43: 2700
D44: 인터넷 | E44: 22000
D45: 기타 구독료 | E45: 3000
D46: 사무공간(해당 시) | E46: 0

Sheet 06.취소교환반품
A1: 작업자 | B1: 접수일 | C1: 플랫폼(판매채널) | D1: 고객명 | E1: 연락처 | F1: 상품 | G1: 내용 | H1: 택배사 | I1: 원송장 | J1: 반송장 | K1: 구매한 플랫폼명(소싱채널) | L1: 계정 | M1: 상태 | N1: 클레임유형 | O1: 고객부담 택배비 | P1: 업체부담 택배비 | Q1: 손실
Q2: =IFERROR(P2-O2,"")
Q3: =IFERROR(P3-O3,"")
Q4: =IFERROR(P4-O4,"")
Q5: =IFERROR(P5-O5,"")
Q6: =IFERROR(P6-O6,"")
Q7: =IFERROR(P7-O7,"")
Q8: =IFERROR(P8-O8,"")
Q9: =IFERROR(P9-O9,"")
Q10: =IFERROR(P10-O10,"")
Q11: =IFERROR(P11-O11,"")
Q12: =IFERROR(P12-O12,"")
Q13: =IFERROR(P13-O13,"")
... Q30: =IFERROR(P30-O30,"")
A33: 총 손실금액 | B33: =SUM(Q2:Q31)

Sheet CS응대스크립트
A1: 문의 유형 | B1: 응대 스크립트 (예시)
A2: 유통기한 및 제조일자 문의 | B2: 안녕하세요 고객님, 해당 제품 수시 입출고 되는 제품으로 최신 제조일자 제품으로 출고되는 점 참고 부탁드립니다.
A3: 배송 관련 문의 | B3: 안녕하세요 고객님, 결제 완료일 기준 출고까지 2~3영업일 소요되는 점 참고 부탁드립니다.
A4: 품절 취소 안내 | B4: [상품명] 주문하신 상품이 업체 수급불가/품절로 배송이 어려워, 취소 및 환불진행 도와드려야 할 것 같습니다. 주문하신 사이트에서 취소신청 해주시면 즉시 환불처리 될 예정이며, 미리 확인해드리지 못해 진심으로 사과말씀 드립니다. 배송에 차질이 생겨 대단히 죄송합니다. 재고 관리에 더욱더 신경쓰도록 하겠습니다. 감사합니다.
A5: 정품 여부 문의 | B5: 안녕하세요 고객님, 저희 스토어에서 판매하는 모든 제품은 브랜드 공식 판매처 및 정식 유통 경로를 통해 입고되는 100% 정품입니다. 가품일 경우 보상 정책이 있으니 안심하고 구매하셔도 좋습니다. 감사합니다.
A6: 상품 파손 및 오배송 | B6: 안녕하세요 고객님, 배송 중 불편을 드려 진심으로 사과말씀 드립니다. 번거로우시겠지만 [파손된 부위/송장 번호가 보이는 박스 사진]을 촬영하여 보내주시면 확인 후 즉시 재배송 또는 환불처리 도와드리겠습니다.
A7: 현금영수증 및 세금계산서 문의 | B7: 안녕하세요 고객님, 결제하신 플랫폼 마이페이지, 내 주문 상세 내역에서 직접 영수증 출력 및 현금영수증 신청이 가능합니다. 직접 발행이 어려우신 경우 고객센터로 문의 주시면 빠른 처리 도와드리겠습니다.
A8: 단순변심 취소 (반품배송비 안내) | B8: [상품명] 안녕하세요 고객님, 해당상품 단순변심으로 인한 취소요청 건으로 접수진행시 왕복 택배비가 발생하는데 그대로 진행 도와드릴까요? 진행 원하시면 아래 계좌로 택배비 입금 후 문앞에 상품 내놔주시면서 문자 남겨주시면 바로 접수 도와드리겠습니다. 감사합니다.
A11: 그대로 복사해서 쓰기보다, 본인 스토어 톤에 맞게 문장을 다듬어 쓰는 것을 추천합니다.

Sheet 소싱금지브랜드
A1: 브랜드/키워드 | B1: 비고(카테고리 등)
A2: 주의사항: 아래 목록은 특정 시점 기준 예시입니다. 상표권 보호·독점유통 계약 등으로 무단 소싱 시 제재(판매중지, 계정정지 등)를 받을 수 있는 브랜드입니다. 목록은 계속 바뀌므로 정기적으로 직접 재확인하고, 새 카테고리에 진입할 때마다 해당 브랜드의 공식 유통 정책을 확인하는 습관을 들이세요.
A3: ㈜아이맘
A4: 남양유업 | B4: 분유
A5: 혜인건강 | B5: 건강기능식품
A6: 보만코리아
A7: 차이슨 | B7: 핸디형 무선청소기
A8: 다이슨 | B8: 무선청소기
A9: 지라프 | B9: 구이바다
A10: ㈜매직랩
A11: 스빈또
A12: ㈜아토세이프
A13: GNM | B13: 자연의품격
A14: 한국존슨앤드존슨
A15: ㈜해맑음푸드 | B15: 자연루
A16: 투데이넛 | B16: 너트한줌
A17: 한국미라클피플사 | B17: 캡슐세제
A18: ㈜제이엠더블유(JMW) | B18: 비네이쳐/드라이기
A19: 닥터루템
A20: 행복을파는사람들 | B20: 래오이경제 흑염소진액
A21: 킨도 | B21: 출산/유아동
A22: 베베숲 | B22: 출산/유아동
A23: 브라운 | B23: 출산/유아동, 가전/면도기
A24: 앙블랑 | B24: 출산/유아동
A25: 베베앙 | B25: 출산/유아동
A26: 코리아나 | B26: 화장품
A27: 일동후디스 | B27: 출산/유아동, 하이뮨
A28: 제이씨코리아 | B28: 데싱디바(네일)
A29: 루디아프레그런스 | B29: 화장품
A30: 이롬 | B30: 황성주
A31: 옐로하나 | B31: 여성청결제
... A46: 필립스 | B46: 면도기
A47: 고투카원
A48: 당당자유 | B48: 건강기능식품
A49: 도담이 | B49: 물티슈
A50: LG | B50: 가전제품
A51: 삼성 | B51: 가전제품
A52: 애플 | B52: 가전제품
A53: 동서식품 | B53: 카누 커피머신(바리스타/어반)
A54: 헬로키티/산리오 | B54: 캐릭터 제품
...
